Workbook

Sheet sheet1
A1: DB 서비스 이름 | B1: DB Role | C1: 상태 | D1: DB Server 이름 | E1: DB Server 타입 | F1: VPC | G1: Subnet | H1: Private 도메인 | I1: Public 도메인 | J1: 생성 일시 | K1: 데이터 스토리지 타입 | L1: 데이터 스토리지 용량 | M1: 데이터 스토리지 암호화 적용 | N1: DB 엔진 버전 | O1: DB Port | P1: 백업 보관일(백업시간)
A2: lms-dev-myd-ats-test | B2: Master | C2: running | D2: lms-dev-myd-ats-test-001-4am7 | E2: G3 - [Standard]2vCPU, 8GB Mem | F2: lms-dev-vpc-01 | G2: lms-dev-sub-prv-test-01 | H2: db-37a9b8-kr1.vpc-cdb.gov-ntruss.com | J2: 2026-01-30 오전 10:03 (UTC+09:00) | K2: CB1 | L2: 3GB | M2: N | N2: MYSQL8.4.6 | O2: 3306 | P2: 1일(07:30)
A3: lms-dev-myd-ats-test | B3: Standby Master | C3: running | D3: lms-dev-myd-ats-test-002-4am8 | E3: G3 - [Standard]2vCPU, 8GB Mem | F3: lms-dev-vpc-01 | G3: lms-dev-sub-prv-test-01 | J3: 2026-01-30 오전 10:03 (UTC+09:00) | K3: CB1 | L3: 3GB | M3: N | N3: MYSQL8.4.6 | O3: 3306 | P3: 1일(07:30)
A4: lms-prd-myd-math-2026 | B4: Master | C4: running | D4: lms-prd-myd-ma-2026-001-49jv | E4: G3 - [Standard]2vCPU, 8GB Mem | F4: lms-prd-vpc-01 | G4: lms-prd-sub-prv-db-05 | H4: db-377mgu-kr1.vpc-cdb.gov-ntruss.com | J4: 2026-01-19 오후 1:34 (UTC+09:00) | K4: CB1 | L4: 26GB | M4: N | N4: MYSQL8.4.6 | O4: 3306 | P4: 7일(00:00)
A5: lms-prd-myd-math-2026 | B5: Standby Master | C5: running | D5: lms-prd-myd-ma-2026-002-49jw | E5: G3 - [Standard]2vCPU, 8GB Mem | F5: lms-prd-vpc-01 | G5: lms-prd-sub-prv-db-05 | J5: 2026-01-19 오후 1:34 (UTC+09:00) | K5: CB1 | L5: 19GB | M5: N | N5: MYSQL8.4.6 | O5: 3306 | P5: 7일(00:00)
A6: lms-prd-myd-eng-2026 | B6: Master | C6: running | D6: lms-prd-myd-eng-2026-001-49iz | E6: G3 - [Standard]2vCPU, 8GB Mem | F6: lms-prd-vpc-01 | G6: lms-prd-sub-prv-db-06 | H6: db-377kt1-kr1.vpc-cdb.gov-ntruss.com | J6: 2026-01-19 오전 9:36 (UTC+09:00) | K6: CB1 | L6: 26GB | M6: N | N6: MYSQL8.4.6 | O6: 3306 | P6: 7일(00:00)
A7: lms-prd-myd-eng-2026 | B7: Standby Master | C7: running | D7: lms-prd-myd-eng-2026-002-49j0 | E7: G3 - [Standard]2vCPU, 8GB Mem | F7: lms-prd-vpc-01 | G7: lms-prd-sub-prv-db-06 | J7: 2026-01-19 오전 9:36 (UTC+09:00) | K7: CB1 | L7: 20GB | M7: N | N7: MYSQL8.4.6 | O7: 3306 | P7: 7일(00:00)
A8: lms-stg-myd-math-2026 | B8: Stand Alone | C8: running | D8: lms-stg-myd-ma-2026-001-49iv | E8: G3 - [Standard]2vCPU, 8GB Mem | F8: lms-stg-vpc-01 | G8: lms-stg-sub-prv-myd-lm-01 | H8: db-377krf-kr1.vpc-cdb.gov-ntruss.com | J8: 2026-01-19 오전 9:31 (UTC+09:00) | K8: CB1 | L8: 20GB | M8: N | N8: MYSQL8.4.6 | O8: 3306 | P8: 3일(00:30)
A9: lms-stg-myd-eng-2026 | B9: Stand Alone | C9: running | D9: lms-stg-myd-eng-2026-001-49ib | E9: G3 - [Standard]2vCPU, 8GB Mem | F9: lms-stg-vpc-01 | G9: lms-stg-sub-prv-myd-lm-02 | H9: db-377kpt-kr1.vpc-cdb.gov-ntruss.com | J9: 2026-01-19 오전 9:27 (UTC+09:00) | K9: CB1 | L9: 19GB | M9: N | N9: MYSQL8.4.6 | O9: 3306 | P9: 3일(00:30)
A10: lms-dev-myd-2026-201 | B10: Stand Alone | C10: running | D10: lms-dev-myd-2026-201-001-48vw | E10: G3 - [Standard]2vCPU, 8GB Mem | F10: lms-dev-vpc-01 | G10: lms-dev-sub-prv-myd-201 | H10: db-376cv4-kr1.vpc-cdb.gov-ntruss.com | J10: 2026-01-12 오전 9:39 (UTC+09:00) | K10: CB1 | L10: 30GB | M10: N | N10: MYSQL8.4.6 | O10: 3306 | P10: 3일(00:30)
A11: lms-prd-myd-math-w-1 | B11: Stand Alone | C11: running | D11: lms-prd-myd-math-w-1-001-44v9 | E11: G3 - [Standard]2vCPU, 8GB Mem | F11: lms-prd-vpc-01 | G11: lms-prd-sub-prv-myd-lw-01 | H11: db-367kf0-kr1.vpc-cdb.gov-ntruss.com | J11: 2025-12-08 오후 1:34 (UTC+09:00) | K11: CB1 | L11: 19GB | M11: N | N11: MYSQL8.0.42 | O11: 3306 | P11: 1일(09:45)
A12: lms-prd-myd-eng-w-01 | B12: Stand Alone | C12: running | D12: lms-prd-myd-eng-w-01-001-44v7 | E12: G3 - [Standard]2vCPU, 8GB Mem | F12: lms-prd-vpc-01 | G12: lms-prd-sub-prv-myd-lm-01 | H12: db-367kcq-kr1.vpc-cdb.gov-ntruss.com | J12: 2025-12-08 오후 1:33 (UTC+09:00) | K12: CB1 | L12: 18GB | M12: N | N12: MYSQL8.0.42 | O12: 3306 | P12: 1일(12:00)
A13: lms-dev-myd-eng-01 | B13: Stand Alone | C13: running | D13: lms-dev-myd-eng-01-001-3ym8 | E13: G3 - [Standard]2vCPU, 8GB Mem | F13: lms-dev-vpc-01 | G13: lms-dev-sub-prv-myd-lw-01 | H13: db-33prej-kr1.vpc-cdb.gov-ntruss.com | J13: 2025-10-24 오후 3:02 (UTC+09:00) | K13: CB1 | L13: 8GB | M13: N | N13: MYSQL8.0.42 | O13: 3306 | P13: 7일(02:00)
A14: lms-dev-myd-math-01 | B14: Stand Alone | C14: running | D14: lms-dev-myd-math-01-001-3ym4 | E14: G3 - [Standard]2vCPU, 8GB Mem | F14: lms-dev-vpc-01 | G14: lms-dev-sub-prv-myd-lm-01 | H14: db-33prct-kr1.vpc-cdb.gov-ntruss.com | J14: 2025-10-24 오후 3:01 (UTC+09:00) | K14: CB1 | L14: 10GB | M14: N | N14: MYSQL8.0.42 | O14: 3306 | P14: 7일(02:00)
A15: lms-prd-myd-lrs-01 | B15: Master | C15: running | D15: lms-prd-myd-lrs-01-001-3ryk | E15: G3 - [Standard]8vCPU, 32GB Mem | F15: lms-prd-vpc-01 | G15: lms-prd-sub-prv-pgd-lrs-01 | H15: db-31q82v-kr1.vpc-cdb.gov-ntruss.com | J15: 2025-09-10 오후 3:15 (UTC+09:00) | K15: CB1 | L15: 134GB | M15: N | N15: MYSQL8.0.42 | O15: 3306 | P15: 7일(00:00)
A16: lms-prd-myd-lrs-01 | B16: Standby Master | C16: running | D16: lms-prd-myd-lrs-01-002-3uh7 | E16: G3 - [Standard]8vCPU, 32GB Mem | F16: lms-prd-vpc-01 | G16: lms-prd-sub-prv-pgd-lrs-01 | J16: 2025-09-21 오전 4:24 (UTC+09:00) | K16: CB1 | L16: 134GB | M16: N | N16: MYSQL8.0.42 | O16: 3306 | P16: 7일(00:00)
A17: stt-prd-myd-001 | B17: Master | C17: running | D17: stt-prd-myd-001-001-3p5d | E17: G3 - [Standard]2vCPU, 8GB Mem | F17: stt-prd-vpc-01 | G17: stt-prd-sub-prv-myd-01 | H17: db-31d308-kr1.vpc-cdb.gov-ntruss.com | J17: 2025-08-22 오후 2:08 (UTC+09:00) | K17: CB1 | L17: 3GB | M17: N | N17: MYSQL8.0.42 | O17: 3306 | P17: 14일(02:00)
A18: stt-prd-myd-001 | B18: Standby Master | C18: running | D18: stt-prd-myd-001-002-3p5e | E18: G3 - [Standard]2vCPU, 8GB Mem | F18: stt-prd-vpc-01 | G18: stt-prd-sub-prv-myd-01 | J18: 2025-08-22 오후 2:08 (UTC+09:00) | K18: CB1 | L18: 3GB | M18: N | N18: MYSQL8.0.42 | O18: 3306 | P18: 14일(02:00)
A19: stt-prd-myd-001 | B19: Slave | C19: running | D19: stt-prd-myd-001-003-3pgn | E19: G3 - [Standard]2vCPU, 8GB Mem | F19: stt-prd-vpc-01 | G19: stt-prd-sub-prv-myd-01 | H19: db-31f3a6-kr1.vpc-cdb.gov-ntruss.com | J19: 2025-08-25 오후 1:27 (UTC+09:00) | K19: CB1 | L19: 3GB | M19: N | N19: MYSQL8.0.42 | O19: 3306 | P19: 14일(02:00)
A20: portal-prd-myd-03 | B20: Stand Alone | C20: running | D20: portal-prd-myd-03-001-3m2y | E20: G3 - [Standard]2vCPU, 8GB Mem | F20: lms-prd-vpc-01 | G20: lms-prd-sub-prv-myd-portal-01 | H20: db-31acmo-kr1.vpc-cdb.gov-ntruss.com | J20: 2025-08-07 오전 11:06 (UTC+09:00) | K20: CB1 | L20: 9GB | M20: N | N20: MYSQL8.0.42 | O20: 3306 | P20: 7일(02:00)
A21: portal-prd-myd-02 | B21: Stand Alone | C21: running | D21: portal-prd-myd-02-001-3m2x | E21: G3 - [Standard]2vCPU, 8GB Mem | F21: lms-prd-vpc-01 | G21: lms-prd-sub-prv-myd-portal-01 | H21: db-31acmi-kr1.vpc-cdb.gov-ntruss.com | J21: 2025-08-07 오전 11:05 (UTC+09:00) | K21: CB1 | L21: 9GB | M21: N | N21: MYSQL8.0.42 | O21: 3306 | P21: 7일(02:00)
A22: portal-prd-myd-01 | B22: Stand Alone | C22: running | D22: portal-prd-myd-01-001-3m2w | E22: G3 - [Standard]2vCPU, 8GB Mem | F22: lms-prd-vpc-01 | G22: lms-prd-sub-prv-myd-portal-01 | H22: db-31acmb-kr1.vpc-cdb.gov-ntruss.com | J22: 2025-08-07 오전 11:04 (UTC+09:00) | K22: CB1 | L22: 9GB | M22: N | N22: MYSQL8.0.42 | O22: 3306 | P22: 7일(02:00)
A23: portal-dev-myd-01 | B23: Stand Alone | C23: running | D23: portal-dev-myd-01-001-3l8k | E23: G3 - [Standard]2vCPU, 8GB Mem | F23: lms-dev-vpc-01 | G23: lms-dev-sub-prv-myd-portal-01 | H23: db-319kn7-kr1.vpc-cdb.gov-ntruss.com | J23: 2025-08-01 오후 12:13 (UTC+09:00) | K23: CB1 | L23: 9GB | M23: N | N23: MYSQL8.0.42 | O23: 3306 | P23: 7일(02:00)
A24: lms-stg-myd-lrs-01 | B24: Stand Alone | C24: running | D24: lms-stg-myd-lrs-01-001-3l1z | E24: G3 - [Standard]2vCPU, 8GB Mem | F24: lms-stg-vpc-01 | G24: lms-stg-sub-prv-lrs-db-20 | H24: db-319f2o-kr1.vpc-cdb.gov-ntruss.com | J24: 2025-07-31 오전 10:00 (UTC+09:00) | K24: CB1 | L24: 251GB | M24: N | N24: MYSQL8.0.42 | O24: 3306 | P24: 7일(02:00)
A25: lms-comm-ncp-01 | B25: Master | C25: running | D25: lms-comm-ncp-01-003-3xfe | E25: G2 - [Standard]2vCPU, 8GB Mem | F25: lms-comm-vpc-01 | G25: lms-comm-sub-prv-ncpdb-01 | H25: db-31931d-kr1.vpc-cdb.gov-ntruss.com | J25: 2025-10-18 오후 8:07 (UTC+09:00) | K25: SSD | L25: 9GB | M25: N | N25: MYSQL8.0.42 | O25: 3306 | P25: 1일(11:45)
A26: lms-comm-ncp-01 | B26: Standby Master | C26: running | D26: lms-comm-ncp-01-004-3xfg | E26: G2 - [Standard]2vCPU, 8GB Mem | F26: lms-comm-vpc-01 | G26: lms-comm-sub-prv-ncpdb-01 | J26: 2025-10-18 오후 8:27 (UTC+09:00) | K26: SSD | L26: 9GB | M26: N | N26: MYSQL8.0.42 | O26: 3306 | P26: 1일(11:45)
A27: lms-stg-etb-03 | B27: Master | C27: running | D27: lms-stg-etb-03-001-3f07 | E27: G3 - [Standard]2vCPU, 8GB Mem | F27: lms-stg-vpc-01 | G27: lms-stg-sub-prv-myd-etb-01 | H27: db-3124ja-kr1.vpc-cdb.gov-ntruss.com | J27: 2025-06-16 오후 2:18 (UTC+09:00) | K27: CB1 | L27: 9GB | M27: N | N27: MYSQL8.0.42 | O27: 3306 | P27: 7일(02:00)
A28: lms-stg-etb-03 | B28: Standby Master | C28: running | D28: lms-stg-etb-03-002-3f08 | E28: G3 - [Standard]2vCPU, 8GB Mem | F28: lms-stg-vpc-01 | G28: lms-stg-sub-prv-myd-etb-01 | J28: 2025-06-16 오후 2:18 (UTC+09:00) | K28: CB1 | L28: 9GB | M28: N | N28: MYSQL8.0.42 | O28: 3306 | P28: 7일(02:00)
A29: lms-stg-csb-03 | B29: Master | C29: running | D29: lms-stg-csb-03-001-3f05 | E29: G3 - [Standard]2vCPU, 8GB Mem | F29: lms-stg-vpc-01 | G29: lms-stg-sub-prv-csb-01 | H29: db-3124it-kr1.vpc-cdb.gov-ntruss.com | J29: 2025-06-16 오후 2:17 (UTC+09:00) | K29: CB1 | L29: 9GB | M29: N | N29: MYSQL8.0.42 | O29: 3306 | P29: 7일(02:00)
A30: lms-stg-csb-03 | B30: Standby Master | C30: running | D30: lms-stg-csb-03-002-3f06 | E30: G3 - [Standard]2vCPU, 8GB Mem | F30: lms-stg-vpc-01 | G30: lms-stg-sub-prv-csb-01 | J30: 2025-06-16 오후 2:17 (UTC+09:00) | K30: CB1 | L30: 9GB | M30: N | N30: MYSQL8.0.42 | O30: 3306 | P30: 7일(02:00)
A31: lms-stg-etb-02 | B31: Master | C31: running | D31: lms-stg-etb-02-003-3ub0 | E31: G2 - [Standard]2vCPU, 8GB Mem | F31: lms-stg-vpc-01 | G31: lms-stg-sub-prv-myd-etb-01 | H31: db-30vr5l-kr1.vpc-cdb.gov-ntruss.com | J31: 2025-09-20 오후 1:11 (UTC+09:00) | K31: SSD | L31: 9GB | M31: N | N31: MYSQL8.0.42 | O31: 3306 | P31: 7일(05:15)
A32: lms-stg-etb-02 | B32: Standby Master | C32: running | D32: lms-stg-etb-02-004-3ub5 | E32: G2 - [Standard]2vCPU, 8GB Mem | F32: lms-stg-vpc-01 | G32: lms-stg-sub-prv-myd-etb-01 | J32: 2025-09-20 오후 1:42 (UTC+09:00) | K32: SSD | L32: 9GB | M32: N | N32: MYSQL8.0.42 | O32: 3306 | P32: 7일(05:15)
A33: lms-stg-csb-02 | B33: Master | C33: running | D33: lms-stg-csb-02-005-44zu | E33: G2 - [Standard]2vCPU, 8GB Mem | F33: lms-stg-vpc-01 | G33: lms-stg-sub-prv-csb-01 | H33: db-30vr47-kr1.vpc-cdb.gov-ntruss.com | J33: 2025-12-09 오후 4:07 (UTC+09:00) | K33: SSD | L33: 9GB | M33: N | N33: MYSQL8.0.42 | O33: 3306 | P33: 7일(02:00)
A34: lms-stg-csb-02 | B34: Standby Master | C34: running | D34: lms-stg-csb-02-006-4500 | E34: G2 - [Standard]2vCPU, 8GB Mem | F34: lms-stg-vpc-01 | G34: lms-stg-sub-prv-csb-01 | J34: 2025-12-09 오후 4:26 (UTC+09:00) | K34: SSD | L34: 9GB | M34: N | N34: MYSQL8.0.42 | O34: 3306 | P34: 7일(02:00)
A35: lms-prd-etb-web-01 | B35: Master | C35: running | D35: lms-prd-etb-w-01-003-3xc5 | E35: G2 - [Standard]2vCPU, 8GB Mem | F35: lms-prd-vpc-01 | G35: lms-prd-sub-prv-myd-etb-01 | H35: db-30k3cf-kr1.vpc-cdb.gov-ntruss.com | J35: 2025-10-17 오후 10:36 (UTC+09:00) | K35: SSD | L35: 9GB | M35: N | N35: MYSQL8.0.42 | O35: 3306 | P35: 7일(02:00)
A36: lms-prd-etb-web-01 | B36: Standby Master | C36: running | D36: lms-prd-etb-w-01-004-3xce | E36: G2 - [Standard]2vCPU, 8GB Mem | F36: lms-prd-vpc-01 | G36: lms-prd-sub-prv-myd-etb-01 | J36: 2025-10-17 오후 10:56 (UTC+09:00) | K36: SSD | L36: 9GB | M36: N | N36: MYSQL8.0.42 | O36: 3306 | P36: 7일(02:00)
A37: lms-prd-csb-w-01 | B37: Master | C37: running | D37: lms-prd-csb-w-01-003-3lds | E37: G2 - [Standard]8vCPU, 32GB Mem | F37: lms-prd-vpc-01 | G37: lms-prd-sub-prv-csb-01 | H37: db-30jak8-kr1.vpc-cdb.gov-ntruss.com | J37: 2025-08-02 오전 11:13 (UTC+09:00) | K37: SSD | L37: 9GB | M37: N | N37: MYSQL8.0.42 | O37: 3306 | P37: 7일(02:00)
A38: lms-prd-csb-w-01 | B38: Standby Master | C38: running | D38: lms-prd-csb-w-01-004-3le4 | E38: G2 - [Standard]8vCPU, 32GB Mem | F38: lms-prd-vpc-01 | G38: lms-prd-sub-prv-csb-01 | J38: 2025-08-02 오전 11:40 (UTC+09:00) | K38: SSD | L38: 9GB | M38: N | N38: MYSQL8.0.42 | O38: 3306 | P38: 7일(02:00)
A39: lms-dev-myd-ats-01 | B39: Stand Alone | C39: running | D39: lms-dev-myd-ats-01-002-3wre | E39: G2 - [Standard]2vCPU, 8GB Mem | F39: lms-dev-vpc-01 | G39: lms-dev-sub-prv-ats-01 | H39: db-30g782-kr1.vpc-cdb.gov-ntruss.com | J39: 2025-10-14 오후 9:54 (UTC+09:00) | K39: SSD | L39: 9GB | M39: N | N39: MYSQL8.0.42 | O39: 3306 | P39: 3일(07:15)
A40: lms-prd-myd-mae34p1083-lm | B40: Master | C40: running | D40: lms-prd-myd-024-lm-005-3uia | E40: G2 - [Standard]16vCPU, 64GB Mem | F40: lms-prd-vpc-01 | G40: lms-prd-sub-prv-myd-lm-08 | H40: db-30fm83-kr1.vpc-cdb.gov-ntruss.com | J40: 2025-09-21 오전 9:10 (UTC+09:00) | K40: SSD | L40: 40GB | M40: N | N40: MYSQL8.0.42 | O40: 3306 | P40: 7일(02:00)
...

Sheet Sheet2
A1: DB 서비스 이름 | B1: DB Role | C1: 상태 | D1: DB Server 이름 | E1: DB Server 타입 | F1: VPC | G1: Subnet | H1: Private 도메인 | I1: Public 도메인 | J1: 생성 일시 | K1: 데이터 스토리지 타입 | L1: 데이터 스토리지 용량 | M1: 데이터 스토리지 암호화 적용 | N1: DB 엔진 버전 | O1: DB Port | P1: 백업 보관일(백업시간) | Q1: 벡업 대상 스키마 | R1: 백업경로 | S1: 백업파일명 | T1: 실행시간 | U1: 주기 | V1: 이름 | W1: 비고 | X1: 학교급 | Y1: 교과서 명 | Z1: 저자
A2: lms-dev-myd-ats-test | B2: Master | C2: running | D2: lms-dev-myd-ats-test-001-4am7 | E2: G3 - [Standard]2vCPU, 8GB Mem | F2: lms-dev-vpc-01 | G2: lms-dev-sub-prv-test-01 | H2: db-37a9b8-kr1.vpc-cdb.gov-ntruss.com | J2: 2026-01-30 오전 10:03 (UTC+09:00) | K2: CB1 | L2: 3GB | M2: N | N2: MYSQL8.4.6 | O2: 3306 | P2: 1일(07:30) | X2: =_xlfn.XLOOKUP(H2, Sheet3!$E:$E, Sheet3!$B:$B, "") | Y2: =_xlfn.XLOOKUP(H2, Sheet3!$E:$E, Sheet3!$C:$C, "") | Z2: =_xlfn.XLOOKUP(H2, Sheet3!$E:$E, Sheet3!$D:$D, "")
A3: lms-dev-myd-ats-test | B3: Standby Master | C3: running | D3: lms-dev-myd-ats-test-002-4am8 | E3: G3 - [Standard]2vCPU, 8GB Mem | F3: lms-dev-vpc-01 | G3: lms-dev-sub-prv-test-01 | J3: 2026-01-30 오전 10:03 (UTC+09:00) | K3: CB1 | L3: 3GB | M3: N | N3: MYSQL8.4.6 | O3: 3306 | P3: 1일(07:30) | X3: =_xlfn.XLOOKUP(H3, Sheet3!$E:$E, Sheet3!$B:$B, "") -> 0 | Y3: =_xlfn.XLOOKUP(H3, Sheet3!$E:$E, Sheet3!$C:$C, "") -> 0 | Z3: =_xlfn.XLOOKUP(H3, Sheet3!$E:$E, Sheet3!$D:$D, "") -> 0
A4: lms-prd-myd-math-2026 | B4: Master | C4: running | D4: lms-prd-myd-ma-2026-001-49jv | E4: G3 - [Standard]2vCPU, 8GB Mem | F4: lms-prd-vpc-01 | G4: lms-prd-sub-prv-db-05 | H4: db-377mgu-kr1.vpc-cdb.gov-ntruss.com | J4: 2026-01-19 오후 1:34 (UTC+09:00) | K4: CB1 | L4: 26GB | M4: N | N4: MYSQL8.4.6 | O4: 3306 | P4: 7일(00:00) | Q4: lms_lrw, lms_cms, lms_lrm | R4: backup/DB_DUMP/PRD2027_BK_백업날짜 | S4: PRD2026_MATH_백업날짜.sql | T4: 0.041666667 | U4: 매일 | V4: prd2026_bk.sh | X4: =_xlfn.XLOOKUP(H4, Sheet3!$E:$E, Sheet3!$B:$B, "") | Y4: =_xlfn.XLOOKUP(H4, Sheet3!$E:$E, Sheet3!$C:$C, "") | Z4: =_xlfn.XLOOKUP(H4, Sheet3!$E:$E, Sheet3!$D:$D, "")
A5: lms-prd-myd-math-2026 | B5: Standby Master | C5: running | D5: lms-prd-myd-ma-2026-002-49jw | E5: G3 - [Standard]2vCPU, 8GB Mem | F5: lms-prd-vpc-01 | G5: lms-prd-sub-prv-db-05 | J5: 2026-01-19 오후 1:34 (UTC+09:00) | K5: CB1 | L5: 19GB | M5: N | N5: MYSQL8.4.6 | O5: 3306 | P5: 7일(00:00) | X5: =_xlfn.XLOOKUP(H5, Sheet3!$E:$E, Sheet3!$B:$B, "") -> 0 | Y5: =_xlfn.XLOOKUP(H5, Sheet3!$E:$E, Sheet3!$C:$C, "") -> 0 | Z5: =_xlfn.XLOOKUP(H5, Sheet3!$E:$E, Sheet3!$D:$D, "") -> 0
A6: lms-prd-myd-eng-2026 | B6: Master | C6: running | D6: lms-prd-myd-eng-2026-001-49iz | E6: G3 - [Standard]2vCPU, 8GB Mem | F6: lms-prd-vpc-01 | G6: lms-prd-sub-prv-db-06 | H6: db-377kt1-kr1.vpc-cdb.gov-ntruss.com | J6: 2026-01-19 오전 9:36 (UTC+09:00) | K6: CB1 | L6: 26GB | M6: N | N6: MYSQL8.4.6 | O6: 3306 | P6: 7일(00:00) | Q6: lms_lrw, lms_cms, lms_lrm | R6: backup/DB_DUMP/PRD2026_BK_백업날짜 | S6: PRD2026_ENG_백업날짜.sql | T6: 0.041666667 | U6: 매일 | V6: prd2026_bk.sh | X6: =_xlfn.XLOOKUP(H6, Sheet3!$E:$E, Sheet3!$B:$B, "") | Y6: =_xlfn.XLOOKUP(H6, Sheet3!$E:$E, Sheet3!$C:$C, "") | Z6: =_xlfn.XLOOKUP(H6, Sheet3!$E:$E, Sheet3!$D:$D, "")
A7: lms-prd-myd-eng-2026 | B7: Standby Master | C7: running | D7: lms-prd-myd-eng-2026-002-49j0 | E7: G3 - [Standard]2vCPU, 8GB Mem | F7: lms-prd-vpc-01 | G7: lms-prd-sub-prv-db-06 | J7: 2026-01-19 오전 9:36 (UTC+09:00) | K7: CB1 | L7: 20GB | M7: N | N7: MYSQL8.4.6 | O7: 3306 | P7: 7일(00:00) | X7: =_xlfn.XLOOKUP(H7, Sheet3!$E:$E, Sheet3!$B:$B, "") -> 0 | Y7: =_xlfn.XLOOKUP(H7, Sheet3!$E:$E, Sheet3!$C:$C, "") -> 0 | Z7: =_xlfn.XLOOKUP(H7, Sheet3!$E:$E, Sheet3!$D:$D, "") -> 0
A8: lms-stg-myd-math-2026 | B8: Stand Alone | C8: running | D8: lms-stg-myd-ma-2026-001-49iv | E8: G3 - [Standard]2vCPU, 8GB Mem | F8: lms-stg-vpc-01 | G8: lms-stg-sub-prv-myd-lm-01 | H8: db-377krf-kr1.vpc-cdb.gov-ntruss.com | J8: 2026-01-19 오전 9:31 (UTC+09:00) | K8: CB1 | L8: 20GB | M8: N | N8: MYSQL8.4.6 | O8: 3306 | P8: 3일(00:30) | Q8: lms_cms, lms_lrm, lms_lrw | R8: /backup/DB_DUMP/STG2026 | S8: stg_2026_math_백업날짜.sql | T8: 0.083333333 | U8: 매일 | V8: stg2026_bk.sh | X8: =_xlfn.XLOOKUP(H8, Sheet3!$E:$E, Sheet3!$B:$B, "") | Y8: =_xlfn.XLOOKUP(H8, Sheet3!$E:$E, Sheet3!$C:$C, "") | Z8: =_xlfn.XLOOKUP(H8, Sheet3!$E:$E, Sheet3!$D:$D, "")
A9: lms-stg-myd-eng-2026 | B9: Stand Alone | C9: running | D9: lms-stg-myd-eng-2026-001-49ib | E9: G3 - [Standard]2vCPU, 8GB Mem | F9: lms-stg-vpc-01 | G9: lms-stg-sub-prv-myd-lm-02 | H9: db-377kpt-kr1.vpc-cdb.gov-ntruss.com | J9: 2026-01-19 오전 9:27 (UTC+09:00) | K9: CB1 | L9: 19GB | M9: N | N9: MYSQL8.4.6 | O9: 3306 | P9: 3일(00:30) | Q9: lms_cms, lms_lrm, lms_lrw | R9: /backup/DB_DUMP/STG2026 | S9: stg_2026_eng_백업날짜.sql | T9: 0.083333333 | U9: 매일 | V9: stg2026_bk.sh | X9: =_xlfn.XLOOKUP(H9, Sheet3!$E:$E, Sheet3!$B:$B, "") | Y9: =_xlfn.XLOOKUP(H9, Sheet3!$E:$E, Sheet3!$C:$C, "") | Z9: =_xlfn.XLOOKUP(H9, Sheet3!$E:$E, Sheet3!$D:$D, "")
A10: lms-dev-myd-2026-201 | B10: Stand Alone | C10: running | D10: lms-dev-myd-2026-201-001-48vw | E10: G3 - [Standard]2vCPU, 8GB Mem | F10: lms-dev-vpc-01 | G10: lms-dev-sub-prv-myd-201 | H10: db-376cv4-kr1.vpc-cdb.gov-ntruss.com | J10: 2026-01-12 오전 9:39 (UTC+09:00) | K10: CB1 | L10: 30GB | M10: N | N10: MYSQL8.4.6 | O10: 3306 | P10: 3일(00:30) | Q10: lms_cms,lms_lrm, lms_lrw | R10: /backup/DB_DUMP/DEV2026 | S10: dev_2026_dump_백업날짜.sql | T10: 0.0625 | U10: 매일 | V10: dev2026_bk.sh | X10: =_xlfn.XLOOKUP(H10, Sheet3!$E:$E, Sheet3!$B:$B, "") | Y10: =_xlfn.XLOOKUP(H10, Sheet3!$E:$E, Sheet3!$C:$C, "") | Z10: =_xlfn.XLOOKUP(H10, Sheet3!$E:$E, Sheet3!$D:$D, "")
A11: lms-prd-myd-math-w-1 | B11: Stand Alone | C11: running | D11: lms-prd-myd-math-w-1-001-44v9 | E11: G3 - [Standard]2vCPU, 8GB Mem | F11: lms-prd-vpc-01 | G11: lms-prd-sub-prv-myd-lw-01 | H11: db-367kf0-kr1.vpc-cdb.gov-ntruss.com | J11: 2025-12-08 오후 1:34 (UTC+09:00) | K11: CB1 | L11: 19GB | M11: N | N11: MYSQL8.0.42 | O11: 3306 | P11: 1일(09:45) | X11: =_xlfn.XLOOKUP(H11, Sheet3!$E:$E, Sheet3!$B:$B, "") | Y11: =_xlfn.XLOOKUP(H11, Sheet3!$E:$E, Sheet3!$C:$C, "") | Z11: =_xlfn.XLOOKUP(H11, Sheet3!$E:$E, Sheet3!$D:$D, "")
A12: lms-prd-myd-eng-w-01 | B12: Stand Alone | C12: running | D12: lms-prd-myd-eng-w-01-001-44v7 | E12: G3 - [Standard]2vCPU, 8GB Mem | F12: lms-prd-vpc-01 | G12: lms-prd-sub-prv-myd-lm-01 | H12: db-367kcq-kr1.vpc-cdb.gov-ntruss.com | J12: 2025-12-08 오후 1:33 (UTC+09:00) | K12: CB1 | L12: 18GB | M12: N | N12: MYSQL8.0.42 | O12: 3306 | P12: 1일(12:00) | X12: =_xlfn.XLOOKUP(H12, Sheet3!$E:$E, Sheet3!$B:$B, "") | Y12: =_xlfn.XLOOKUP(H12, Sheet3!$E:$E, Sheet3!$C:$C, "") | Z12: =_xlfn.XLOOKUP(H12, Sheet3!$E:$E, Sheet3!$D:$D, "")
A13: lms-dev-myd-eng-01 | B13: Stand Alone | C13: running | D13: lms-dev-myd-eng-01-001-3ym8 | E13: G3 - [Standard]2vCPU, 8GB Mem | F13: lms-dev-vpc-01 | G13: lms-dev-sub-prv-myd-lw-01 | H13: db-33prej-kr1.vpc-cdb.gov-ntruss.com | J13: 2025-10-24 오후 3:02 (UTC+09:00) | K13: CB1 | L13: 8GB | M13: N | N13: MYSQL8.0.42 | O13: 3306 | P13: 7일(02:00) | X13: =_xlfn.XLOOKUP(H13, Sheet3!$E:$E, Sheet3!$B:$B, "") | Y13: =_xlfn.XLOOKUP(H13, Sheet3!$E:$E, Sheet3!$C:$C, "") | Z13: =_xlfn.XLOOKUP(H13, Sheet3!$E:$E, Sheet3!$D:$D, "")
A14: lms-dev-myd-math-01 | B14: Stand Alone | C14: running | D14: lms-dev-myd-math-01-001-3ym4 | E14: G3 - [Standard]2vCPU, 8GB Mem | F14: lms-dev-vpc-01 | G14: lms-dev-sub-prv-myd-lm-01 | H14: db-33prct-kr1.vpc-cdb.gov-ntruss.com | J14: 2025-10-24 오후 3:01 (UTC+09:00) | K14: CB1 | L14: 10GB | M14: N | N14: MYSQL8.0.42 | O14: 3306 | P14: 7일(02:00) | X14: =_xlfn.XLOOKUP(H14, Sheet3!$E:$E, Sheet3!$B:$B, "") | Y14: =_xlfn.XLOOKUP(H14, Sheet3!$E:$E, Sheet3!$C:$C, "") | Z14: =_xlfn.XLOOKUP(H14, Sheet3!$E:$E, Sheet3!$D:$D, "")
A15: lms-prd-myd-lrs-01 | B15: Master | C15: running | D15: lms-prd-myd-lrs-01-001-3ryk | E15: G3 - [Standard]8vCPU, 32GB Mem | F15: lms-prd-vpc-01 | G15: lms-prd-sub-prv-pgd-lrs-01 | H15: db-31q82v-kr1.vpc-cdb.gov-ntruss.com | J15: 2025-09-10 오후 3:15 (UTC+09:00) | K15: CB1 | L15: 134GB | M15: N | N15: MYSQL8.0.42 | O15: 3306 | P15: 7일(00:00) | X15: =_xlfn.XLOOKUP(H15, Sheet3!$E:$E, Sheet3!$B:$B, "") | Y15: =_xlfn.XLOOKUP(H15, Sheet3!$E:$E, Sheet3!$C:$C, "") | Z15: =_xlfn.XLOOKUP(H15, Sheet3!$E:$E, Sheet3!$D:$D, "")
A16: lms-prd-myd-lrs-01 | B16: Standby Master | C16: running | D16: lms-prd-myd-lrs-01-002-3uh7 | E16: G3 - [Standard]8vCPU, 32GB Mem | F16: lms-prd-vpc-01 | G16: lms-prd-sub-prv-pgd-lrs-01 | J16: 2025-09-21 오전 4:24 (UTC+09:00) | K16: CB1 | L16: 134GB | M16: N | N16: MYSQL8.0.42 | O16: 3306 | P16: 7일(00:00) | X16: =_xlfn.XLOOKUP(H16, Sheet3!$E:$E, Sheet3!$B:$B, "") -> 0 | Y16: =_xlfn.XLOOKUP(H16, Sheet3!$E:$E, Sheet3!$C:$C, "") -> 0 | Z16: =_xlfn.XLOOKUP(H16, Sheet3!$E:$E, Sheet3!$D:$D, "") -> 0
A17: stt-prd-myd-001 | B17: Master | C17: running | D17: stt-prd-myd-001-001-3p5d | E17: G3 - [Standard]2vCPU, 8GB Mem | F17: stt-prd-vpc-01 | G17: stt-prd-sub-prv-myd-01 | H17: db-31d308-kr1.vpc-cdb.gov-ntruss.com | J17: 2025-08-22 오후 2:08 (UTC+09:00) | K17: CB1 | L17: 3GB | M17: N | N17: MYSQL8.0.42 | O17: 3306 | P17: 14일(02:00) | X17: =_xlfn.XLOOKUP(H17, Sheet3!$E:$E, Sheet3!$B:$B, "") | Y17: =_xlfn.XLOOKUP(H17, Sheet3!$E:$E, Sheet3!$C:$C, "") | Z17: =_xlfn.XLOOKUP(H17, Sheet3!$E:$E, Sheet3!$D:$D, "")
A18: stt-prd-myd-001 | B18: Standby Master | C18: running | D18: stt-prd-myd-001-002-3p5e | E18: G3 - [Standard]2vCPU, 8GB Mem | F18: stt-prd-vpc-01 | G18: stt-prd-sub-prv-myd-01 | J18: 2025-08-22 오후 2:08 (UTC+09:00) | K18: CB1 | L18: 3GB | M18: N | N18: MYSQL8.0.42 | O18: 3306 | P18: 14일(02:00) | X18: =_xlfn.XLOOKUP(H18, Sheet3!$E:$E, Sheet3!$B:$B, "") -> 0 | Y18: =_xlfn.XLOOKUP(H18, Sheet3!$E:$E, Sheet3!$C:$C, "") -> 0 | Z18: =_xlfn.XLOOKUP(H18, Sheet3!$E:$E, Sheet3!$D:$D, "") -> 0
A19: stt-prd-myd-001 | B19: Slave | C19: running | D19: stt-prd-myd-001-003-3pgn | E19: G3 - [Standard]2vCPU, 8GB Mem | F19: stt-prd-vpc-01 | G19: stt-prd-sub-prv-myd-01 | H19: db-31f3a6-kr1.vpc-cdb.gov-ntruss.com | J19: 2025-08-25 오후 1:27 (UTC+09:00) | K19: CB1 | L19: 3GB | M19: N | N19: MYSQL8.0.42 | O19: 3306 | P19: 14일(02:00) | X19: =_xlfn.XLOOKUP(H19, Sheet3!$E:$E, Sheet3!$B:$B, "") | Y19: =_xlfn.XLOOKUP(H19, Sheet3!$E:$E, Sheet3!$C:$C, "") | Z19: =_xlfn.XLOOKUP(H19, Sheet3!$E:$E, Sheet3!$D:$D, "")
A20: portal-prd-myd-03 | B20: Stand Alone | C20: running | D20: portal-prd-myd-03-001-3m2y | E20: G3 - [Standard]2vCPU, 8GB Mem | F20: lms-prd-vpc-01 | G20: lms-prd-sub-prv-myd-portal-01 | H20: db-31acmo-kr1.vpc-cdb.gov-ntruss.com | J20: 2025-08-07 오전 11:06 (UTC+09:00) | K20: CB1 | L20: 9GB | M20: N | N20: MYSQL8.0.42 | O20: 3306 | P20: 7일(02:00) | X20: =_xlfn.XLOOKUP(H20, Sheet3!$E:$E, Sheet3!$B:$B, "") | Y20: =_xlfn.XLOOKUP(H20, Sheet3!$E:$E, Sheet3!$C:$C, "") | Z20: =_xlfn.XLOOKUP(H20, Sheet3!$E:$E, Sheet3!$D:$D, "")
A21: portal-prd-myd-02 | B21: Stand Alone | C21: running | D21: portal-prd-myd-02-001-3m2x | E21: G3 - [Standard]2vCPU, 8GB Mem | F21: lms-prd-vpc-01 | G21: lms-prd-sub-prv-myd-portal-01 | H21: db-31acmi-kr1.vpc-cdb.gov-ntruss.com | J21: 2025-08-07 오전 11:05 (UTC+09:00) | K21: CB1 | L21: 9GB | M21: N | N21: MYSQL8.0.42 | O21: 3306 | P21: 7일(02:00) | X21: =_xlfn.XLOOKUP(H21, Sheet3!$E:$E, Sheet3!$B:$B, "") | Y21: =_xlfn.XLOOKUP(H21, Sheet3!$E:$E, Sheet3!$C:$C, "") | Z21: =_xlfn.XLOOKUP(H21, Sheet3!$E:$E, Sheet3!$D:$D, "")
A22: portal-prd-myd-01 | B22: Stand Alone | C22: running | D22: portal-prd-myd-01-001-3m2w | E22: G3 - [Standard]2vCPU, 8GB Mem | F22: lms-prd-vpc-01 | G22: lms-prd-sub-prv-myd-portal-01 | H22: db-31acmb-kr1.vpc-cdb.gov-ntruss.com | J22: 2025-08-07 오전 11:04 (UTC+09:00) | K22: CB1 | L22: 9GB | M22: N | N22: MYSQL8.0.42 | O22: 3306 | P22: 7일(02:00) | X22: =_xlfn.XLOOKUP(H22, Sheet3!$E:$E, Sheet3!$B:$B, "") | Y22: =_xlfn.XLOOKUP(H22, Sheet3!$E:$E, Sheet3!$C:$C, "") | Z22: =_xlfn.XLOOKUP(H22, Sheet3!$E:$E, Sheet3!$D:$D, "")
A23: portal-dev-myd-01 | B23: Stand Alone | C23: running | D23: portal-dev-myd-01-001-3l8k | E23: G3 - [Standard]2vCPU, 8GB Mem | F23: lms-dev-vpc-01 | G23: lms-dev-sub-prv-myd-portal-01 | H23: db-319kn7-kr1.vpc-cdb.gov-ntruss.com | J23: 2025-08-01 오후 12:13 (UTC+09:00) | K23: CB1 | L23: 9GB | M23: N | N23: MYSQL8.0.42 | O23: 3306 | P23: 7일(02:00) | X23: =_xlfn.XLOOKUP(H23, Sheet3!$E:$E, Sheet3!$B:$B, "") | Y23: =_xlfn.XLOOKUP(H23, Sheet3!$E:$E, Sheet3!$C:$C, "") | Z23: =_xlfn.XLOOKUP(H23, Sheet3!$E:$E, Sheet3!$D:$D, "")
A24: lms-stg-myd-lrs-01 | B24: Stand Alone | C24: running | D24: lms-stg-myd-lrs-01-001-3l1z | E24: G3 - [Standard]2vCPU, 8GB Mem | F24: lms-stg-vpc-01 | G24: lms-stg-sub-prv-lrs-db-20 | H24: db-319f2o-kr1.vpc-cdb.gov-ntruss.com | J24: 2025-07-31 오전 10:00 (UTC+09:00) | K24: CB1 | L24: 251GB | M24: N | N24: MYSQL8.0.42 | O24: 3306 | P24: 7일(02:00) | X24: =_xlfn.XLOOKUP(H24, Sheet3!$E:$E, Sheet3!$B:$B, "") | Y24: =_xlfn.XLOOKUP(H24, Sheet3!$E:$E, Sheet3!$C:$C, "") | Z24: =_xlfn.XLOOKUP(H24, Sheet3!$E:$E, Sheet3!$D:$D, "")
A25: lms-comm-ncp-01 | B25: Master | C25: running | D25: lms-comm-ncp-01-003-3xfe | E25: G2 - [Standard]2vCPU, 8GB Mem | F25: lms-comm-vpc-01 | G25: lms-comm-sub-prv-ncpdb-01 | H25: db-31931d-kr1.vpc-cdb.gov-ntruss.com | J25: 2025-10-18 오후 8:07 (UTC+09:00) | K25: SSD | L25: 9GB | M25: N | N25: MYSQL8.0.42 | O25: 3306 | P25: 1일(11:45) | X25: =_xlfn.XLOOKUP(H25, Sheet3!$E:$E, Sheet3!$B:$B, "") | Y25: =_xlfn.XLOOKUP(H25, Sheet3!$E:$E, Sheet3!$C:$C, "") | Z25: =_xlfn.XLOOKUP(H25, Sheet3!$E:$E, Sheet3!$D:$D, "")
A26: lms-comm-ncp-01 | B26: Standby Master | C26: running | D26: lms-comm-ncp-01-004-3xfg | E26: G2 - [Standard]2vCPU, 8GB Mem | F26: lms-comm-vpc-01 | G26: lms-comm-sub-prv-ncpdb-01 | J26: 2025-10-18 오후 8:27 (UTC+09:00) | K26: SSD | L26: 9GB | M26: N | N26: MYSQL8.0.42 | O26: 3306 | P26: 1일(11:45) | X26: =_xlfn.XLOOKUP(H26, Sheet3!$E:$E, Sheet3!$B:$B, "") -> 0 | Y26: =_xlfn.XLOOKUP(H26, Sheet3!$E:$E, Sheet3!$C:$C, "") -> 0 | Z26: =_xlfn.XLOOKUP(H26, Sheet3!$E:$E, Sheet3!$D:$D, "") -> 0
A27: lms-stg-etb-03 | B27: Master | C27: running | D27: lms-stg-etb-03-001-3f07 | E27: G3 - [Standard]2vCPU, 8GB Mem | F27: lms-stg-vpc-01 | G27: lms-stg-sub-prv-myd-etb-01 | H27: db-3124ja-kr1.vpc-cdb.gov-ntruss.com | J27: 2025-06-16 오후 2:18 (UTC+09:00) | K27: CB1 | L27: 9GB | M27: N | N27: MYSQL8.0.42 | O27: 3306 | P27: 7일(02:00) | X27: =_xlfn.XLOOKUP(H27, Sheet3!$E:$E, Sheet3!$B:$B, "") | Y27: =_xlfn.XLOOKUP(H27, Sheet3!$E:$E, Sheet3!$C:$C, "") | Z27: =_xlfn.XLOOKUP(H27, Sheet3!$E:$E, Sheet3!$D:$D, "")
A28: lms-stg-etb-03 | B28: Standby Master | C28: running | D28: lms-stg-etb-03-002-3f08 | E28: G3 - [Standard]2vCPU, 8GB Mem | F28: lms-stg-vpc-01 | G28: lms-stg-sub-prv-myd-etb-01 | J28: 2025-06-16 오후 2:18 (UTC+09:00) | K28: CB1 | L28: 9GB | M28: N | N28: MYSQL8.0.42 | O28: 3306 | P28: 7일(02:00) | X28: =_xlfn.XLOOKUP(H28, Sheet3!$E:$E, Sheet3!$B:$B, "") -> 0 | Y28: =_xlfn.XLOOKUP(H28, Sheet3!$E:$E, Sheet3!$C:$C, "") -> 0 | Z28: =_xlfn.XLOOKUP(H28, Sheet3!$E:$E, Sheet3!$D:$D, "") -> 0
A29: lms-stg-csb-03 | B29: Master | C29: running | D29: lms-stg-csb-03-001-3f05 | E29: G3 - [Standard]2vCPU, 8GB Mem | F29: lms-stg-vpc-01 | G29: lms-stg-sub-prv-csb-01 | H29: db-3124it-kr1.vpc-cdb.gov-ntruss.com | J29: 2025-06-16 오후 2:17 (UTC+09:00) | K29: CB1 | L29: 9GB | M29: N | N29: MYSQL8.0.42 | O29: 3306 | P29: 7일(02:00) | X29: =_xlfn.XLOOKUP(H29, Sheet3!$E:$E, Sheet3!$B:$B, "") | Y29: =_xlfn.XLOOKUP(H29, Sheet3!$E:$E, Sheet3!$C:$C, "") | Z29: =_xlfn.XLOOKUP(H29, Sheet3!$E:$E, Sheet3!$D:$D, "")
A30: lms-stg-csb-03 | B30: Standby Master | C30: running | D30: lms-stg-csb-03-002-3f06 | E30: G3 - [Standard]2vCPU, 8GB Mem | F30: lms-stg-vpc-01 | G30: lms-stg-sub-prv-csb-01 | J30: 2025-06-16 오후 2:17 (UTC+09:00) | K30: CB1 | L30: 9GB | M30: N | N30: MYSQL8.0.42 | O30: 3306 | P30: 7일(02:00) | X30: =_xlfn.XLOOKUP(H30, Sheet3!$E:$E, Sheet3!$B:$B, "") -> 0 | Y30: =_xlfn.XLOOKUP(H30, Sheet3!$E:$E, Sheet3!$C:$C, "") -> 0 | Z30: =_xlfn.XLOOKUP(H30, Sheet3!$E:$E, Sheet3!$D:$D, "") -> 0
A31: lms-stg-etb-02 | B31: Master | C31: running | D31: lms-stg-etb-02-003-3ub0 | E31: G2 - [Standard]2vCPU, 8GB Mem | F31: lms-stg-vpc-01 | G31: lms-stg-sub-prv-myd-etb-01 | H31: db-30vr5l-kr1.vpc-cdb.gov-ntruss.com | J31: 2025-09-20 오후 1:11 (UTC+09:00) | K31: SSD | L31: 9GB | M31: N | N31: MYSQL8.0.42 | O31: 3306 | P31: 7일(05:15) | X31: =_xlfn.XLOOKUP(H31, Sheet3!$E:$E, Sheet3!$B:$B, "") | Y31: =_xlfn.XLOOKUP(H31, Sheet3!$E:$E, Sheet3!$C:$C, "") | Z31: =_xlfn.XLOOKUP(H31, Sheet3!$E:$E, Sheet3!$D:$D, "")
A32: lms-stg-etb-02 | B32: Standby Master | C32: running | D32: lms-stg-etb-02-004-3ub5 | E32: G2 - [Standard]2vCPU, 8GB Mem | F32: lms-stg-vpc-01 | G32: lms-stg-sub-prv-myd-etb-01 | J32: 2025-09-20 오후 1:42 (UTC+09:00) | K32: SSD | L32: 9GB | M32: N | N32: MYSQL8.0.42 | O32: 3306 | P32: 7일(05:15) | X32: =_xlfn.XLOOKUP(H32, Sheet3!$E:$E, Sheet3!$B:$B, "") -> 0 | Y32: =_xlfn.XLOOKUP(H32, Sheet3!$E:$E, Sheet3!$C:$C, "") -> 0 | Z32: =_xlfn.XLOOKUP(H32, Sheet3!$E:$E, Sheet3!$D:$D, "") -> 0
A33: lms-stg-csb-02 | B33: Master | C33: running | D33: lms-stg-csb-02-005-44zu | E33: G2 - [Standard]2vCPU, 8GB Mem | F33: lms-stg-vpc-01 | G33: lms-stg-sub-prv-csb-01 | H33: db-30vr47-kr1.vpc-cdb.gov-ntruss.com | J33: 2025-12-09 오후 4:07 (UTC+09:00) | K33: SSD | L33: 9GB | M33: N | N33: MYSQL8.0.42 | O33: 3306 | P33: 7일(02:00) | X33: =_xlfn.XLOOKUP(H33, Sheet3!$E:$E, Sheet3!$B:$B, "") | Y33: =_xlfn.XLOOKUP(H33, Sheet3!$E:$E, Sheet3!$C:$C, "") | Z33: =_xlfn.XLOOKUP(H33, Sheet3!$E:$E, Sheet3!$D:$D, "")
A34: lms-stg-csb-02 | B34: Standby Master | C34: running | D34: lms-stg-csb-02-006-4500 | E34: G2 - [Standard]2vCPU, 8GB Mem | F34: lms-stg-vpc-01 | G34: lms-stg-sub-prv-csb-01 | J34: 2025-12-09 오후 4:26 (UTC+09:00) | K34: SSD | L34: 9GB | M34: N | N34: MYSQL8.0.42 | O34: 3306 | P34: 7일(02:00) | X34: =_xlfn.XLOOKUP(H34, Sheet3!$E:$E, Sheet3!$B:$B, "") -> 0 | Y34: =_xlfn.XLOOKUP(H34, Sheet3!$E:$E, Sheet3!$C:$C, "") -> 0 | Z34: =_xlfn.XLOOKUP(H34, Sheet3!$E:$E, Sheet3!$D:$D, "") -> 0
A35: lms-prd-etb-web-01 | B35: Master | C35: running | D35: lms-prd-etb-w-01-003-3xc5 | E35: G2 - [Standard]2vCPU, 8GB Mem | F35: lms-prd-vpc-01 | G35: lms-prd-sub-prv-myd-etb-01 | H35: db-30k3cf-kr1.vpc-cdb.gov-ntruss.com | J35: 2025-10-17 오후 10:36 (UTC+09:00) | K35: SSD | L35: 9GB | M35: N | N35: MYSQL8.0.42 | O35: 3306 | P35: 7일(02:00) | X35: =_xlfn.XLOOKUP(H35, Sheet3!$E:$E, Sheet3!$B:$B, "") | Y35: =_xlfn.XLOOKUP(H35, Sheet3!$E:$E, Sheet3!$C:$C, "") | Z35: =_xlfn.XLOOKUP(H35, Sheet3!$E:$E, Sheet3!$D:$D, "")
A36: lms-prd-etb-web-01 | B36: Standby Master | C36: running | D36: lms-prd-etb-w-01-004-3xce | E36: G2 - [Standard]2vCPU, 8GB Mem | F36: lms-prd-vpc-01 | G36: lms-prd-sub-prv-myd-etb-01 | J36: 2025-10-17 오후 10:56 (UTC+09:00) | K36: SSD | L36: 9GB | M36: N | N36: MYSQL8.0.42 | O36: 3306 | P36: 7일(02:00) | X36: =_xlfn.XLOOKUP(H36, Sheet3!$E:$E, Sheet3!$B:$B, "") -> 0 | Y36: =_xlfn.XLOOKUP(H36, Sheet3!$E:$E, Sheet3!$C:$C, "") -> 0 | Z36: =_xlfn.XLOOKUP(H36, Sheet3!$E:$E, Sheet3!$D:$D, "") -> 0
A37: lms-prd-csb-w-01 | B37: Master | C37: running | D37: lms-prd-csb-w-01-003-3lds | E37: G2 - [Standard]8vCPU, 32GB Mem | F37: lms-prd-vpc-01 | G37: lms-prd-sub-prv-csb-01 | H37: db-30jak8-kr1.vpc-cdb.gov-ntruss.com | J37: 2025-08-02 오전 11:13 (UTC+09:00) | K37: SSD | L37: 9GB | M37: N | N37: MYSQL8.0.42 | O37: 3306 | P37: 7일(02:00) | X37: =_xlfn.XLOOKUP(H37, Sheet3!$E:$E, Sheet3!$B:$B, "") | Y37: =_xlfn.XLOOKUP(H37, Sheet3!$E:$E, Sheet3!$C:$C, "") | Z37: =_xlfn.XLOOKUP(H37, Sheet3!$E:$E, Sheet3!$D:$D, "")
A38: lms-prd-csb-w-01 | B38: Standby Master | C38: running | D38: lms-prd-csb-w-01-004-3le4 | E38: G2 - [Standard]8vCPU, 32GB Mem | F38: lms-prd-vpc-01 | G38: lms-prd-sub-prv-csb-01 | J38: 2025-08-02 오전 11:40 (UTC+09:00) | K38: SSD | L38: 9GB | M38: N | N38: MYSQL8.0.42 | O38: 3306 | P38: 7일(02:00) | X38: =_xlfn.XLOOKUP(H38, Sheet3!$E:$E, Sheet3!$B:$B, "") -> 0 | Y38: =_xlfn.XLOOKUP(H38, Sheet3!$E:$E, Sheet3!$C:$C, "") -> 0 | Z38: =_xlfn.XLOOKUP(H38, Sheet3!$E:$E, Sheet3!$D:$D, "") -> 0
A39: lms-dev-myd-ats-01 | B39: Stand Alone | C39: running | D39: lms-dev-myd-ats-01-002-3wre | E39: G2 - [Standard]2vCPU, 8GB Mem | F39: lms-dev-vpc-01 | G39: lms-dev-sub-prv-ats-01 | H39: db-30g782-kr1.vpc-cdb.gov-ntruss.com | J39: 2025-10-14 오후 9:54 (UTC+09:00) | K39: SSD | L39: 9GB | M39: N | N39: MYSQL8.0.42 | O39: 3306 | P39: 3일(07:15) | X39: =_xlfn.XLOOKUP(H39, Sheet3!$E:$E, Sheet3!$B:$B, "") | Y39: =_xlfn.XLOOKUP(H39, Sheet3!$E:$E, Sheet3!$C:$C, "") | Z39: =_xlfn.XLOOKUP(H39, Sheet3!$E:$E, Sheet3!$D:$D, "")
A40: lms-prd-myd-mae34p1083-lm | B40: Master | C40: running | D40: lms-prd-myd-024-lm-005-3uia | E40: G2 - [Standard]16vCPU, 64GB Mem | F40: lms-prd-vpc-01 | G40: lms-prd-sub-prv-myd-lm-08 | H40: db-30fm83-kr1.vpc-cdb.gov-ntruss.com | J40: 2025-09-21 오전 9:10 (UTC+09:00) | K40: SSD | L40: 40GB | M40: N | N40: MYSQL8.0.42 | O40: 3306 | P40: 7일(02:00) | Q40: lms_ath, lms_cms, lms_lrm | R40: /backup/DB_DUMP/PRD_LRM_BK_백업날짜 | S40: LRM_PRD8_4_2_백업날짜.sql | T40: 0.125 | U40: 매일 | V40: lrm_prd_bk.sh | X40: 초등 | Y40: 수학 4-2 | Z40: 박만구
...

Sheet Sheet3
A1: LMS PRD LW DB 현황 | B1: 학교급 | C1: 교과서 명 | D1: 저자 | E1: 접속정보
B2: 초등 | C2: 영어 3 | D2: 이동환 | E2: db-2nmn5-kr1.vpc-cdb.gov-ntruss.com
B3: 초등 | C3: 영어 4 | D3: 이동환 | E3: db-308ufr-kr1.vpc-cdb.gov-ntruss.com
B4: 초등 | C4: 영어 3 | D4: 김태은 | E4: db-2o1ai-kr1.vpc-cdb.gov-ntruss.com
B5: 초등 | C5: 영어 4 | D5: 김태은 | E5: db-308ugs-kr1.vpc-cdb.gov-ntruss.com
B6: 초등 | C6: 영어 3 | D6: 함순애 | E6: db-2nmqc-kr1.vpc-cdb.gov-ntruss.com
B7: 초등 | C7: 영어 4 | D7: 함순애 | E7: db-308uik-kr1.vpc-cdb.gov-ntruss.com
B8: 중학 | C8: 영어 | D8: 이상기 | E8: db-2nms0-kr1.vpc-cdb.gov-ntruss.com
B9: 중학 | C9: 영어 | D9: 소영순 | E9: db-2nmtt-kr1.vpc-cdb.gov-ntruss.com
B10: 고등 | C10: 공통영어 1 | D10: 강상구 | E10: db-2nmv1-kr1.vpc-cdb.gov-ntruss.com
B11: 고등 | C11: 공통영어 2 | D11: 강상구 | E11: db-308ujk-kr1.vpc-cdb.gov-ntruss.com
B12: 고등 | C12: 공통영어 1 | D12: 조수경 | E12: db-2nn03-kr1.vpc-cdb.gov-ntruss.com
B13: 고등 | C13: 공통영어 2 | D13: 조수경 | E13: db-308ukf-kr1.vpc-cdb.gov-ntruss.com
... B27: 고등 | C27: 공통수학2 | D27: 홍진곤 | E27: db-308un0-kr1.vpc-cdb.gov-ntruss.com
A29: LMS PRD LW DB 현황 | B29: 초등 | C29: 영어 3 | D29: 이동환 | E29: db-2nmrj-kr1.vpc-cdb.gov-ntruss.com
B30: 초등 | C30: 영어 4 | D30: 이동환 | E30: db-308unj-kr1.vpc-cdb.gov-ntruss.com
B31: 초등 | C31: 영어 3 | D31: 김태은 | E31: db-2o1a4-kr1.vpc-cdb.gov-ntruss.com
B32: 초등 | C32: 영어 4 | D32: 김태은 | E32: db-308uo0-kr1.vpc-cdb.gov-ntruss.com
B33: 초등 | C33: 영어 3 | D33: 함순애 | E33: db-2nmpr-kr1.vpc-cdb.gov-ntruss.com
B34: 초등 | C34: 영어 4 | D34: 함순애 | E34: db-308uok-kr1.vpc-cdb.gov-ntruss.com
B35: 중학 | C35: 영어 | D35: 이상기 | E35: db-2nmqs-kr1.vpc-cdb.gov-ntruss.com
B36: 중학 | C36: 영어 | D36: 소영순 | E36: db-2nmsn-kr1.vpc-cdb.gov-ntruss.com
B37: 고등 | C37: 공통영어 1 | D37: 강상구 | E37: db-2nmue-kr1.vpc-cdb.gov-ntruss.com
B38: 고등 | C38: 공통영어 2 | D38: 강상구 | E38: db-308up5-kr1.vpc-cdb.gov-ntruss.com
B39: 고등 | C39: 공통영어 1 | D39: 조수경 | E39: db-2nmvf-kr1.vpc-cdb.gov-ntruss.com
B40: 고등 | C40: 공통영어 2 | D40: 조수경 | E40: db-308upl-kr1.vpc-cdb.gov-ntruss.com
B41: 초등 | C41: 수학 3-1 | D41: 박만구 | E41: db-2nn0r-kr1.vpc-cdb.gov-ntruss.com
... B54: 고등 | C54: 공통수학2 | D54: 홍진곤 | E54: db-308usp-kr1.vpc-cdb.gov-ntruss.com
